#VRML_SIM R2019a utf8
WorldInfo {
}
Viewpoint {
  orientation 0.9999663501139302 -0.006503837762912656 -0.004999873416250896 4.972356460784229
  position 0.06513465191542789 12.478266371544485 3.398019386531964
}
TexturedBackground {
}
TexturedBackgroundLight {
}
Floor {
}
Solid {
  translation 0 0 -2.6600000000000015
  scale 0.3 0.3 0.3
  children [
    PhoneBooth {
    }
  ]
}
Transform {
  children [
    Gnome {
      translation 4.102911669525356 0 -3.454473242395032
      rotation 0 1 0 4.974188353
    }
  ]
}
Robot {
  translation 0 0.10000000000000002 0
  children [
    DEF BODY Shape {
      appearance DEF PINE_GREEN RoughPine {
        colorOverride 0.010070954451819639 0.5033340962844282 0.15786984054322117
      }
      geometry Cylinder {
        height 0.08
        radius 0.14
      }
    }
    DEF TOP_TANK Group {
      children [
        DEF TOP1 Transform {
          translation 0 0.07000000000000003 0
          children [
            DEF BASE Shape {
              appearance DEF PINE_GREEN RoughPine {
                colorOverride 0.010070954451819639 0.5033340962844282 0.15786984054322117
              }
              geometry Cylinder {
                height 0.1
                radius 0.12
              }
            }
          ]
        }
        DEF TOP2_DIS_GUN Transform {
          translation 0 0.15 0
          children [
            Shape {
              appearance DEF PINE_GREEN RoughPine {
                colorOverride 0.010070954451819639 0.5033340962844282 0.15786984054322117
              }
              geometry Cylinder {
                height 0.1
                radius 0.08
              }
            }
            HingeJoint {
              jointParameters HingeJointParameters {
                axis 0 1 0
              }
              device [
                PositionSensor {
                  name "mobile_position"
                }
                RotationalMotor {
                  name "mobile_motor"
                }
              ]
              endPoint Solid {
                translation 0.001703708443917297 0.019999999999999997 -0.10294095400591444
                rotation 0 1 0 1.570796283640826
                children [
                  DEF SENSOR_GUN Group {
                    children [
                      DEF BARRA Shape {
                        appearance PBRAppearance {
                          baseColor 0 0 0
                        }
                        geometry Box {
                          size 0.08 0.02 0.06
                        }
                      }
                      DEF DIS_MOB Transform {
                        children [
                          DEF DS_MOBILE_GUN DistanceSensor {
                            translation 0.04 0 -3.469446951953614e-18
                            children [
                              Shape {
                                appearance DEF PINK PBRAppearance {
                                  baseColor 0.9333333333333333 0.33600366216525523 0.33600366216525523
                                }
                                geometry DEF BOX_DS Box {
                                  size 0.02 0.02 0.04
                                }
                              }
                            ]
                            name "ds_mobile"
                            lookupTable [
                              0.1 0 0
                              2 1023 0
                            ]
                            resolution 1
                          }
                        ]
                      }
                    ]
                  }
                ]
                name "solid(3)"
              }
            }
          ]
        }
        DEF TOP3 Transform {
          translation 0 0.21000000000000002 0
          children [
            Shape {
              appearance DEF PINE_GREEN RoughPine {
                colorOverride 0.010070954451819639 0.5033340962844282 0.15786984054322117
              }
              geometry Sphere {
                radius 0.06
              }
            }
            HingeJoint {
              jointParameters HingeJointParameters {
                axis 0 1 0
                anchor 0 0.05 0
              }
              device [
                PositionSensor {
                  name "gun_position"
                }
                RotationalMotor {
                  name "gun_motor"
                }
              ]
              endPoint Solid {
                translation -1.150775107150448e-09 0.03000000302078501 -0.10999999841768404
                rotation -0.5773502664212908 0.5773502747262954 -0.5773502664212908 2.094395119003205
                children [
                  Group {
                    children [
                      Shape {
                        appearance DEF PINE_GREEN RoughPine {
                          colorOverride 0.010070954451819639 0.5033340962844282 0.15786984054322117
                        }
                        geometry Cylinder {
                          height 0.25
                          radius 0.015
                        }
                      }
                    ]
                  }
                ]
                name "solid(4)"
              }
            }
          ]
        }
      ]
    }
    DEF DS_DOWN DistanceSensor {
      translation 0.005884569420668858 0 -0.1399999951674819
      rotation 0 -1 0 4.712389004359173
      children [
        Shape {
          appearance PBRAppearance {
            baseColor 0.9333333333333333 0.33600366216525523 0.33600366216525523
          }
          geometry Box {
            size 0.04 0.02 0.1
          }
        }
      ]
      name "ds_down"
      lookupTable [
        0.05 0 0
        0.4 255 0
      ]
      resolution 1
    }
    DEF WH_1 Transform {
      translation 0 0 0.14
      children [
        DEF WHEEL1 HingeJoint {
          jointParameters HingeJointParameters {
            axis 0 0 1
            anchor 0 0 0.02
          }
          device [
            RotationalMotor {
              name "wheel1"
              maxVelocity 30.3687
              maxTorque 0.8473
            }
            PositionSensor {
              name "ps_1"
              resolution 0.003848
            }
          ]
          endPoint Solid {
            translation 0 0 -0.009999999999999998
            rotation 0 0 1 0
            children [
              DEF sr1 HingeJoint {
                jointParameters HingeJointParameters {
                  anchor 0 0.06 0.02
                }
                endPoint Solid {
                  translation 0 0.06 0.02
                  rotation 1 0 0 0
                  children [
                    DEF r1 Transform {
                      rotation 0 0 1 1.5708
                      children [
                        DEF SMALL_WHEEL_SHAPE Shape {
                          appearance PBRAppearance {
                            baseColor 1 0.752941 0.796078
                            roughness 1
                            metalness 0
                          }
                          geometry Cylinder {
                            height 0.03
                            radius 0.012
                          }
                        }
                      ]
                    }
                  ]
                  name "sr1"
                  boundingObject USE r1
                  physics Physics {
                    density -1
                    mass 0.1
                  }
                }
              }
              DEF sr2 HingeJoint {
                jointParameters HingeJointParameters {
                  axis 0.707107 0.707107 0
                  anchor -0.04535 0.04535 0.02
                }
                endPoint Solid {
                  translation -0.04535 0.04535 0.02
                  rotation 0.7071067811865476 0.7071067811865476 0 0
                  children [
                    DEF r2 Transform {
                      rotation 0 0 1 2.27
                      children [
                        USE SMALL_WHEEL_SHAPE
                      ]
                    }
                  ]
                  name "sr2"
                  boundingObject USE r2
                  physics Physics {
                    density -1
                    mass 0.1
                  }
                }
              }
              DEF sr3 HingeJoint {
                jointParameters HingeJointParameters {
                  anchor 0 -0.06 0.02
                }
                endPoint Solid {
                  translation 0 -0.06 0.02
                  rotation 1 0 0 0
                  children [
                    DEF r3 Transform {
                      rotation 0 0 1 1.5708
                      children [
                        USE SMALL_WHEEL_SHAPE
                      ]
                    }
                  ]
                  name "sr3"
                  boundingObject USE r3
                  physics Physics {
                    density -1
                    mass 0.1
                  }
                }
              }
              DEF sr4 HingeJoint {
                jointParameters HingeJointParameters {
                  axis 0.707107 0.707107 0
                  anchor 0.04535 -0.04535 0.02
                }
                endPoint Solid {
                  translation 0.04535 -0.04535 0.02
                  rotation 0.7071067811865476 0.7071067811865476 0 0
                  children [
                    DEF r4 Transform {
                      rotation 0 0 1 2.27
                      children [
                        USE SMALL_WHEEL_SHAPE
                      ]
                    }
                  ]
                  name "sr4"
                  boundingObject USE r4
                  physics Physics {
                    density -1
                    mass 0.1
                  }
                }
              }
              DEF sr5 HingeJoint {
                jointParameters HingeJointParameters {
                  axis 0 1 0
                  anchor -0.06 0 0.02
                }
                endPoint Solid {
                  translation -0.06 0 0.02
                  children [
                    DEF r5 Transform {
                      children [
                        USE SMALL_WHEEL_SHAPE
                      ]
                    }
                  ]
                  name "sr5"
                  boundingObject USE r5
                  physics Physics {
                    density -1
                    mass 0.1
                  }
                }
              }
              DEF sr6 HingeJoint {
                jointParameters HingeJointParameters {
                  axis 0 1 0
                  anchor 0.06 0 0.02
                }
                endPoint Solid {
                  translation 0.06 0 0.02
                  children [
                    DEF r6 Transform {
                      children [
                        USE SMALL_WHEEL_SHAPE
                      ]
                    }
                  ]
                  name "sr6"
                  boundingObject USE r6
                  physics Physics {
                    density -1
                    mass 0.1
                  }
                }
              }
              DEF sr7 HingeJoint {
                jointParameters HingeJointParameters {
                  axis -0.707107 0.707107 0
                  anchor -0.04535 -0.04535 0.02
                }
                endPoint Solid {
                  translation -0.04535 -0.04535 0.02
                  rotation -0.7071067811865476 0.7071067811865476 0 0
                  children [
                    DEF r7 Transform {
                      rotation 0 0 1 0.76
                      children [
                        USE SMALL_WHEEL_SHAPE
                      ]
                    }
                  ]
                  name "sr7"
                  boundingObject USE r7
                  physics Physics {
                    density -1
                    mass 0.1
                  }
                }
              }
              DEF sr8 HingeJoint {
                jointParameters HingeJointParameters {
                  axis -0.707107 0.707107 0
                  anchor 0.04535 0.04535 0.02
                }
                endPoint Solid {
                  translation 0.04535 0.04535 0.02
                  rotation -0.7071067811865476 0.7071067811865476 0 0
                  children [
                    DEF r8 Transform {
                      rotation 0 0 1 0.76
                      children [
                        USE SMALL_WHEEL_SHAPE
                      ]
                    }
                  ]
                  name "sr8"
                  boundingObject USE r8
                  physics Physics {
                    density -1
                    mass 0.1
                  }
                }
              }
              DEF WHEEL_TRANS Transform {
                translation 0 0 0.02
                rotation 1 0 0 1.5708
                children [
                  DEF WHEEL_SHAPE Shape {
                    appearance PBRAppearance {
                      baseColor 0.9333333333333333 0.33600366216525523 0.33600366216525523
                      roughness 1
                    }
                    geometry Cylinder {
                      height 0.02
                      radius 0.06
                      subdivision 20
                    }
                  }
                ]
              }
            ]
            boundingObject USE WHEEL_TRANS
            physics Physics {
            }
          }
        }
      ]
    }
    DEF WH_2 Transform {
      translation 0.13 0 -0.069
      rotation 0 1 0 2.094395096
      children [
        DEF WHEEL1 HingeJoint {
          jointParameters HingeJointParameters {
            axis 0 0 1
            anchor 0 0 0.02
          }
          device [
            RotationalMotor {
              name "wheel2"
              maxVelocity 30.3687
              maxTorque 0.8473
            }
            PositionSensor {
              name "ps_2"
              resolution 0.003848
            }
          ]
          endPoint Solid {
            translation 0 0 -0.009999999999999998
            rotation 0 0 1 0
            children [
              DEF sr1 HingeJoint {
                jointParameters HingeJointParameters {
                  anchor 0 0.06 0.02
                }
                endPoint Solid {
                  translation 0 0.06 0.02
                  rotation 1 0 0 0
                  children [
                    DEF r1 Transform {
                      rotation 0 0 1 1.5708
                      children [
                        DEF SMALL_WHEEL_SHAPE Shape {
                          appearance PBRAppearance {
                            baseColor 1 0.752941 0.796078
                            roughness 1
                            metalness 0
                          }
                          geometry Cylinder {
                            height 0.03
                            radius 0.012
                          }
                        }
                      ]
                    }
                  ]
                  name "sr1"
                  boundingObject USE r1
                  physics Physics {
                    density -1
                    mass 0.1
                  }
                }
              }
              DEF sr2 HingeJoint {
                jointParameters HingeJointParameters {
                  axis 0.707107 0.707107 0
                  anchor -0.04535 0.04535 0.02
                }
                endPoint Solid {
                  translation -0.04535 0.04535 0.02
                  rotation 0.7071067811865476 0.7071067811865476 0 0
                  children [
                    DEF r2 Transform {
                      rotation 0 0 1 2.27
                      children [
                        USE SMALL_WHEEL_SHAPE
                      ]
                    }
                  ]
                  name "sr2"
                  boundingObject USE r2
                  physics Physics {
                    density -1
                    mass 0.1
                  }
                }
              }
              DEF sr3 HingeJoint {
                jointParameters HingeJointParameters {
                  anchor 0 -0.06 0.02
                }
                endPoint Solid {
                  translation 0 -0.06 0.02
                  rotation 1 0 0 0
                  children [
                    DEF r3 Transform {
                      rotation 0 0 1 1.5708
                      children [
                        USE SMALL_WHEEL_SHAPE
                      ]
                    }
                  ]
                  name "sr3"
                  boundingObject USE r3
                  physics Physics {
                    density -1
                    mass 0.1
                  }
                }
              }
              DEF sr4 HingeJoint {
                jointParameters HingeJointParameters {
                  axis 0.707107 0.707107 0
                  anchor 0.04535 -0.04535 0.02
                }
                endPoint Solid {
                  translation 0.04535 -0.04535 0.02
                  rotation 0.7071067811865476 0.7071067811865476 0 0
                  children [
                    DEF r4 Transform {
                      rotation 0 0 1 2.27
                      children [
                        USE SMALL_WHEEL_SHAPE
                      ]
                    }
                  ]
                  name "sr4"
                  boundingObject USE r4
                  physics Physics {
                    density -1
                    mass 0.1
                  }
                }
              }
              DEF sr5 HingeJoint {
                jointParameters HingeJointParameters {
                  axis 0 1 0
                  anchor -0.06 0 0.02
                }
                endPoint Solid {
                  translation -0.06 0 0.02
                  children [
                    DEF r5 Transform {
                      children [
                        USE SMALL_WHEEL_SHAPE
                      ]
                    }
                  ]
                  name "sr5"
                  boundingObject USE r5
                  physics Physics {
                    density -1
                    mass 0.1
                  }
                }
              }
              DEF sr6 HingeJoint {
                jointParameters HingeJointParameters {
                  axis 0 1 0
                  anchor 0.06 0 0.02
                }
                endPoint Solid {
                  translation 0.06 0 0.02
                  children [
                    DEF r6 Transform {
                      children [
                        USE SMALL_WHEEL_SHAPE
                      ]
                    }
                  ]
                  name "sr6"
                  boundingObject USE r6
                  physics Physics {
                    density -1
                    mass 0.1
                  }
                }
              }
              DEF sr7 HingeJoint {
                jointParameters HingeJointParameters {
                  axis -0.707107 0.707107 0
                  anchor -0.04535 -0.04535 0.02
                }
                endPoint Solid {
                  translation -0.04535 -0.04535 0.02
                  rotation -0.7071067811865476 0.7071067811865476 0 0
                  children [
                    DEF r7 Transform {
                      rotation 0 0 1 0.76
                      children [
                        USE SMALL_WHEEL_SHAPE
                      ]
                    }
                  ]
                  name "sr7"
                  boundingObject USE r7
                  physics Physics {
                    density -1
                    mass 0.1
                  }
                }
              }
              DEF sr8 HingeJoint {
                jointParameters HingeJointParameters {
                  axis -0.707107 0.707107 0
                  anchor 0.04535 0.04535 0.02
                }
                endPoint Solid {
                  translation 0.04535 0.04535 0.02
                  rotation -0.7071067811865476 0.7071067811865476 0 0
                  children [
                    DEF r8 Transform {
                      rotation 0 0 1 0.76
                      children [
                        USE SMALL_WHEEL_SHAPE
                      ]
                    }
                  ]
                  name "sr8"
                  boundingObject USE r8
                  physics Physics {
                    density -1
                    mass 0.1
                  }
                }
              }
              DEF WHEEL_TRANS Transform {
                translation 0 0 0.02
                rotation 1 0 0 1.5708
                children [
                  USE WHEEL_SHAPE
                ]
              }
            ]
            name "solid(1)"
            boundingObject USE WHEEL_TRANS
            physics Physics {
            }
          }
        }
      ]
    }
    DEF WH_3 Transform {
      translation -0.13 0 -0.069
      rotation 0 0.9999999999999999 0 -2.0944
      children [
        DEF WHEEL1 HingeJoint {
          jointParameters HingeJointParameters {
            axis 0 0 1
            anchor 0 0 0.02
          }
          device [
            RotationalMotor {
              name "wheel3"
              maxVelocity 30.3687
              maxTorque 0.8473
            }
            PositionSensor {
              name "ps_3"
              resolution 0.003848
            }
          ]
          endPoint Solid {
            translation 0 0 -0.009999999999999998
            rotation 0 0 1 0
            children [
              DEF sr1 HingeJoint {
                jointParameters HingeJointParameters {
                  anchor 0 0.06 0.02
                }
                endPoint Solid {
                  translation 0 0.06 0.02
                  rotation 1 0 0 0
                  children [
                    DEF r1 Transform {
                      rotation 0 0 1 1.5708
                      children [
                        DEF SMALL_WHEEL_SHAPE Shape {
                          appearance PBRAppearance {
                            baseColor 1 0.752941 0.796078
                            roughness 1
                            metalness 0
                          }
                          geometry Cylinder {
                            height 0.03
                            radius 0.012
                          }
                        }
                      ]
                    }
                  ]
                  name "sr1"
                  boundingObject USE r1
                  physics Physics {
                    density -1
                    mass 0.1
                  }
                }
              }
              DEF sr2 HingeJoint {
                jointParameters HingeJointParameters {
                  axis 0.707107 0.707107 0
                  anchor -0.04535 0.04535 0.02
                }
                endPoint Solid {
                  translation -0.04535 0.04535 0.02
                  rotation 0.7071067811865476 0.7071067811865476 0 0
                  children [
                    DEF r2 Transform {
                      rotation 0 0 1 2.27
                      children [
                        USE SMALL_WHEEL_SHAPE
                      ]
                    }
                  ]
                  name "sr2"
                  boundingObject USE r2
                  physics Physics {
                    density -1
                    mass 0.1
                  }
                }
              }
              DEF sr3 HingeJoint {
                jointParameters HingeJointParameters {
                  anchor 0 -0.06 0.02
                }
                endPoint Solid {
                  translation 0 -0.06 0.02
                  rotation 1 0 0 0
                  children [
                    DEF r3 Transform {
                      rotation 0 0 1 1.5708
                      children [
                        USE SMALL_WHEEL_SHAPE
                      ]
                    }
                  ]
                  name "sr3"
                  boundingObject USE r3
                  physics Physics {
                    density -1
                    mass 0.1
                  }
                }
              }
              DEF sr4 HingeJoint {
                jointParameters HingeJointParameters {
                  axis 0.707107 0.707107 0
                  anchor 0.04535 -0.04535 0.02
                }
                endPoint Solid {
                  translation 0.04535 -0.04535 0.02
                  rotation 0.7071067811865476 0.7071067811865476 0 0
                  children [
                    DEF r4 Transform {
                      rotation 0 0 1 2.27
                      children [
                        USE SMALL_WHEEL_SHAPE
                      ]
                    }
                  ]
                  name "sr4"
                  boundingObject USE r4
                  physics Physics {
                    density -1
                    mass 0.1
                  }
                }
              }
              DEF sr5 HingeJoint {
                jointParameters HingeJointParameters {
                  axis 0 1 0
                  anchor -0.06 0 0.02
                }
                endPoint Solid {
                  translation -0.06 0 0.02
                  children [
                    DEF r5 Transform {
                      children [
                        USE SMALL_WHEEL_SHAPE
                      ]
                    }
                  ]
                  name "sr5"
                  boundingObject USE r5
                  physics Physics {
                    density -1
                    mass 0.1
                  }
                }
              }
              DEF sr6 HingeJoint {
                jointParameters HingeJointParameters {
                  axis 0 1 0
                  anchor 0.06 0 0.02
                }
                endPoint Solid {
                  translation 0.06 0 0.02
                  children [
                    DEF r6 Transform {
                      children [
                        USE SMALL_WHEEL_SHAPE
                      ]
                    }
                  ]
                  name "sr6"
                  boundingObject USE r6
                  physics Physics {
                    density -1
                    mass 0.1
                  }
                }
              }
              DEF sr7 HingeJoint {
                jointParameters HingeJointParameters {
                  axis -0.707107 0.707107 0
                  anchor -0.04535 -0.04535 0.02
                }
                endPoint Solid {
                  translation -0.04535 -0.04535 0.02
                  rotation -0.7071067811865476 0.7071067811865476 0 0
                  children [
                    DEF r7 Transform {
                      rotation 0 0 1 0.76
                      children [
                        USE SMALL_WHEEL_SHAPE
                      ]
                    }
                  ]
                  name "sr7"
                  boundingObject USE r7
                  physics Physics {
                    density -1
                    mass 0.1
                  }
                }
              }
              DEF sr8 HingeJoint {
                jointParameters HingeJointParameters {
                  axis -0.707107 0.707107 0
                  anchor 0.04535 0.04535 0.02
                }
                endPoint Solid {
                  translation 0.04535 0.04535 0.02
                  rotation -0.7071067811865476 0.7071067811865476 0 0
                  children [
                    DEF r8 Transform {
                      rotation 0 0 1 0.76
                      children [
                        USE SMALL_WHEEL_SHAPE
                      ]
                    }
                  ]
                  name "sr8"
                  boundingObject USE r8
                  physics Physics {
                    density -1
                    mass 0.1
                  }
                }
              }
              DEF WHEEL_TRANS Transform {
                translation 0 0 0.02
                rotation 1 0 0 1.5708
                children [
                  USE WHEEL_SHAPE
                ]
              }
            ]
            name "solid(2)"
            boundingObject USE WHEEL_TRANS
            physics Physics {
            }
          }
        }
      ]
    }
  ]
  boundingObject USE BODY
  physics Physics {
  }
  controller "u3_real_exam_munoz_samara"
}
