#VRML_SIM R2019a utf8
WorldInfo {
}
Viewpoint {
  orientation 0.8194537144418703 -0.4923934566000803 -0.2933330765270882 5.0259716042276015
  position 2.5497929296639557 3.656954828582798 1.3322735935422858
}
TexturedBackground {
}
TexturedBackgroundLight {
}
Floor {
}
Robot {
  translation 0 0.10000000000000002 0
  rotation 0 1 0 1.0471975479999998
  children [
    DEF BODY Shape {
      appearance DEF PINE_GREEN RoughPine {
        colorOverride 0.010070954451819639 0.5033340962844282 0.15786984054322117
      }
      geometry Cylinder {
        height 0.08
        radius 0.14
      }
    }
    DEF TOP_TANK Group {
      children [
        DEF TOP1 Transform {
          translation 0 0.07000000000000003 0
          children [
            DEF BASE Shape {
              appearance DEF PINE_GREEN RoughPine {
                colorOverride 0.010070954451819639 0.5033340962844282 0.15786984054322117
              }
              geometry Cylinder {
                height 0.1
                radius 0.12
              }
            }
          ]
        }
        DEF TOP2 Transform {
          translation 0 0.15 0
          children [
            Shape {
              appearance DEF PINE_GREEN RoughPine {
                colorOverride 0.010070954451819639 0.5033340962844282 0.15786984054322117
              }
              geometry Cylinder {
                height 0.1
                radius 0.08
              }
            }
            HingeJoint {
              jointParameters HingeJointParameters {
                axis 0 1 0
              }
              device [
                PositionSensor {
                  name "ds_position"
                }
                RotationalMotor {
                  name "ds_motor"
                }
              ]
              endPoint Solid {
                translation 0.07 0.01 0
                children [
                  DEF SENSORS Group {
                    children [
                      DEF BARRA Shape {
                        appearance PBRAppearance {
                          baseColor 0 0 0
                        }
                        geometry Box {
                          size 0.08 0.02 0.06
                        }
                      }
                      DEF DIS_SENSORS Transform {
                        children [
                          DEF DS_LEFT DistanceSensor {
                            translation 0.04 0 0.03
                            children [
                              Shape {
                                appearance DEF PINK PBRAppearance {
                                  baseColor 0.9333333333333333 0.33600366216525523 0.33600366216525523
                                }
                                geometry DEF BOX_DS Box {
                                  size 0.02 0.02 0.02
                                }
                              }
                            ]
                            name "ds_left"
                            lookupTable [
                              0.05 0 0
                              0.4 255 0
                            ]
                            resolution 1
                          }
                          DEF DS_RIGHT DistanceSensor {
                            translation 0.04 0 -0.03
                            children [
                              Shape {
                                appearance USE PINK
                                geometry USE BOX_DS
                              }
                            ]
                            name "ds_right"
                            lookupTable [
                              0.05 0 0
                              0.4 255 0
                            ]
                            resolution 1
                          }
                        ]
                      }
                    ]
                  }
                ]
                name "solid(3)"
              }
            }
          ]
        }
        DEF TOP3 Transform {
          translation 0 0.21000000000000002 0
          children [
            Shape {
              appearance DEF PINE_GREEN RoughPine {
                colorOverride 0.010070954451819639 0.5033340962844282 0.15786984054322117
              }
              geometry Sphere {
                radius 0.06
              }
            }
            HingeJoint {
              jointParameters HingeJointParameters {
                axis 0 1 0
                anchor 0 0.05 0
              }
              device [
                PositionSensor {
                  name "gun_position"
                }
                RotationalMotor {
                  name "gun_motor"
                }
              ]
              endPoint Solid {
                translation 0.1100000004315407 0.030000001438469 0
                rotation 0 0 0.9999999999999999 4.712388966
                children [
                  Group {
                    children [
                      Shape {
                        appearance DEF PINE_GREEN RoughPine {
                          colorOverride 0.010070954451819639 0.5033340962844282 0.15786984054322117
                        }
                        geometry Cylinder {
                          height 0.25
                          radius 0.015
                        }
                      }
                      DEF GUN_BAR_DS Transform {
                        children [
                          DEF GUN_DS DistanceSensor {
                            translation 6.233365214768519e-10 0.12999999999999995 0
                            rotation 0 0 -1 4.7123890043591725
                            children [
                              Shape {
                                appearance PBRAppearance {
                                  baseColor 0 0 0
                                }
                                geometry Box {
                                  size 0.02 0.02 0.02
                                }
                              }
                            ]
                            name "ds_gun"
                            lookupTable [
                              0 0 0
                              0.1 0 0
                              2 1023 0
                            ]
                            resolution 1
                          }
                        ]
                      }
                    ]
                  }
                ]
                name "solid(4)"
              }
            }
          ]
        }
      ]
    }
    DEF WH_1 Transform {
      translation 0 0 0.14
      children [
        DEF WHEEL1 HingeJoint {
          jointParameters HingeJointParameters {
            axis 0 0 1
            anchor 0 0 0.02
          }
          device [
            RotationalMotor {
              name "wheel1"
              maxVelocity 30.3687
              maxTorque 0.8473
            }
            PositionSensor {
              name "ps_1"
              resolution 0.003848
            }
          ]
          endPoint Solid {
            translation 0 0 -0.009999999999999998
            rotation 0 0 1 0
            children [
              DEF sr1 HingeJoint {
                jointParameters HingeJointParameters {
                  anchor 0 0.06 0.02
                }
                endPoint Solid {
                  translation 0 0.06 0.02
                  rotation 1 0 0 0
                  children [
                    DEF r1 Transform {
                      rotation 0 0 1 1.5708
                      children [
                        DEF SMALL_WHEEL_SHAPE Shape {
                          appearance PBRAppearance {
                            baseColor 1 0.752941 0.796078
                            roughness 1
                            metalness 0
                          }
                          geometry Cylinder {
                            height 0.03
                            radius 0.012
                          }
                        }
                      ]
                    }
                  ]
                  name "sr1"
                  boundingObject USE r1
                  physics Physics {
                    density -1
                    mass 0.1
                  }
                }
              }
              DEF sr2 HingeJoint {
                jointParameters HingeJointParameters {
                  axis 0.707107 0.707107 0
                  anchor -0.04535 0.04535 0.02
                }
                endPoint Solid {
                  translation -0.04535 0.04535 0.02
                  rotation 0.7071067811865476 0.7071067811865476 0 0
                  children [
                    DEF r2 Transform {
                      rotation 0 0 1 2.27
                      children [
                        USE SMALL_WHEEL_SHAPE
                      ]
                    }
                  ]
                  name "sr2"
                  boundingObject USE r2
                  physics Physics {
                    density -1
                    mass 0.1
                  }
                }
              }
              DEF sr3 HingeJoint {
                jointParameters HingeJointParameters {
                  anchor 0 -0.06 0.02
                }
                endPoint Solid {
                  translation 0 -0.06 0.02
                  rotation 1 0 0 0
                  children [
                    DEF r3 Transform {
                      rotation 0 0 1 1.5708
                      children [
                        USE SMALL_WHEEL_SHAPE
                      ]
                    }
                  ]
                  name "sr3"
                  boundingObject USE r3
                  physics Physics {
                    density -1
                    mass 0.1
                  }
                }
              }
              DEF sr4 HingeJoint {
                jointParameters HingeJointParameters {
                  axis 0.707107 0.707107 0
                  anchor 0.04535 -0.04535 0.02
                }
                endPoint Solid {
                  translation 0.04535 -0.04535 0.02
                  rotation 0.7071067811865476 0.7071067811865476 0 0
                  children [
                    DEF r4 Transform {
                      rotation 0 0 1 2.27
                      children [
                        USE SMALL_WHEEL_SHAPE
                      ]
                    }
                  ]
                  name "sr4"
                  boundingObject USE r4
                  physics Physics {
                    density -1
                    mass 0.1
                  }
                }
              }
              DEF sr5 HingeJoint {
                jointParameters HingeJointParameters {
                  axis 0 1 0
                  anchor -0.06 0 0.02
                }
                endPoint Solid {
                  translation -0.06 0 0.02
                  children [
                    DEF r5 Transform {
                      children [
                        USE SMALL_WHEEL_SHAPE
                      ]
                    }
                  ]
                  name "sr5"
                  boundingObject USE r5
                  physics Physics {
                    density -1
                    mass 0.1
                  }
                }
              }
              DEF sr6 HingeJoint {
                jointParameters HingeJointParameters {
                  axis 0 1 0
                  anchor 0.06 0 0.02
                }
                endPoint Solid {
                  translation 0.06 0 0.02
                  children [
                    DEF r6 Transform {
                      children [
                        USE SMALL_WHEEL_SHAPE
                      ]
                    }
                  ]
                  name "sr6"
                  boundingObject USE r6
                  physics Physics {
                    density -1
                    mass 0.1
                  }
                }
              }
              DEF sr7 HingeJoint {
                jointParameters HingeJointParameters {
                  axis -0.707107 0.707107 0
                  anchor -0.04535 -0.04535 0.02
                }
                endPoint Solid {
                  translation -0.04535 -0.04535 0.02
                  rotation -0.7071067811865476 0.7071067811865476 0 0
                  children [
                    DEF r7 Transform {
                      rotation 0 0 1 0.76
                      children [
                        USE SMALL_WHEEL_SHAPE
                      ]
                    }
                  ]
                  name "sr7"
                  boundingObject USE r7
                  physics Physics {
                    density -1
                    mass 0.1
                  }
                }
              }
              DEF sr8 HingeJoint {
                jointParameters HingeJointParameters {
                  axis -0.707107 0.707107 0
                  anchor 0.04535 0.04535 0.02
                }
                endPoint Solid {
                  translation 0.04535 0.04535 0.02
                  rotation -0.7071067811865476 0.7071067811865476 0 0
                  children [
                    DEF r8 Transform {
                      rotation 0 0 1 0.76
                      children [
                        USE SMALL_WHEEL_SHAPE
                      ]
                    }
                  ]
                  name "sr8"
                  boundingObject USE r8
                  physics Physics {
                    density -1
                    mass 0.1
                  }
                }
              }
              DEF WHEEL_TRANS Transform {
                translation 0 0 0.02
                rotation 1 0 0 1.5708
                children [
                  DEF WHEEL_SHAPE Shape {
                    appearance PBRAppearance {
                      baseColor 0.9333333333333333 0.33600366216525523 0.33600366216525523
                      roughness 1
                    }
                    geometry Cylinder {
                      height 0.02
                      radius 0.06
                      subdivision 20
                    }
                  }
                ]
              }
            ]
            boundingObject USE WHEEL_TRANS
            physics Physics {
            }
          }
        }
      ]
    }
    DEF WH_2 Transform {
      translation 0.13 0 -0.069
      rotation 0 1 0 2.094395096
      children [
        DEF WHEEL1 HingeJoint {
          jointParameters HingeJointParameters {
            axis 0 0 1
            anchor 0 0 0.02
          }
          device [
            RotationalMotor {
              name "wheel2"
              maxVelocity 30.3687
              maxTorque 0.8473
            }
            PositionSensor {
              name "ps_2"
              resolution 0.003848
            }
          ]
          endPoint Solid {
            translation 0 0 -0.009999999999999998
            rotation 0 0 1 0
            children [
              DEF sr1 HingeJoint {
                jointParameters HingeJointParameters {
                  anchor 0 0.06 0.02
                }
                endPoint Solid {
                  translation 0 0.06 0.02
                  rotation 1 0 0 0
                  children [
                    DEF r1 Transform {
                      rotation 0 0 1 1.5708
                      children [
                        DEF SMALL_WHEEL_SHAPE Shape {
                          appearance PBRAppearance {
                            baseColor 1 0.752941 0.796078
                            roughness 1
                            metalness 0
                          }
                          geometry Cylinder {
                            height 0.03
                            radius 0.012
                          }
                        }
                      ]
                    }
                  ]
                  name "sr1"
                  boundingObject USE r1
                  physics Physics {
                    density -1
                    mass 0.1
                  }
                }
              }
              DEF sr2 HingeJoint {
                jointParameters HingeJointParameters {
                  axis 0.707107 0.707107 0
                  anchor -0.04535 0.04535 0.02
                }
                endPoint Solid {
                  translation -0.04535 0.04535 0.02
                  rotation 0.7071067811865476 0.7071067811865476 0 0
                  children [
                    DEF r2 Transform {
                      rotation 0 0 1 2.27
                      children [
                        USE SMALL_WHEEL_SHAPE
                      ]
                    }
                  ]
                  name "sr2"
                  boundingObject USE r2
                  physics Physics {
                    density -1
                    mass 0.1
                  }
                }
              }
              DEF sr3 HingeJoint {
                jointParameters HingeJointParameters {
                  anchor 0 -0.06 0.02
                }
                endPoint Solid {
                  translation 0 -0.06 0.02
                  rotation 1 0 0 0
                  children [
                    DEF r3 Transform {
                      rotation 0 0 1 1.5708
                      children [
                        USE SMALL_WHEEL_SHAPE
                      ]
                    }
                  ]
                  name "sr3"
                  boundingObject USE r3
                  physics Physics {
                    density -1
                    mass 0.1
                  }
                }
              }
              DEF sr4 HingeJoint {
                jointParameters HingeJointParameters {
                  axis 0.707107 0.707107 0
                  anchor 0.04535 -0.04535 0.02
                }
                endPoint Solid {
                  translation 0.04535 -0.04535 0.02
                  rotation 0.7071067811865476 0.7071067811865476 0 0
                  children [
                    DEF r4 Transform {
                      rotation 0 0 1 2.27
                      children [
                        USE SMALL_WHEEL_SHAPE
                      ]
                    }
                  ]
                  name "sr4"
                  boundingObject USE r4
                  physics Physics {
                    density -1
                    mass 0.1
                  }
                }
              }
              DEF sr5 HingeJoint {
                jointParameters HingeJointParameters {
                  axis 0 1 0
                  anchor -0.06 0 0.02
                }
                endPoint Solid {
                  translation -0.06 0 0.02
                  children [
                    DEF r5 Transform {
                      children [
                        USE SMALL_WHEEL_SHAPE
                      ]
                    }
                  ]
                  name "sr5"
                  boundingObject USE r5
                  physics Physics {
                    density -1
                    mass 0.1
                  }
                }
              }
              DEF sr6 HingeJoint {
                jointParameters HingeJointParameters {
                  axis 0 1 0
                  anchor 0.06 0 0.02
                }
                endPoint Solid {
                  translation 0.06 0 0.02
                  children [
                    DEF r6 Transform {
                      children [
                        USE SMALL_WHEEL_SHAPE
                      ]
                    }
                  ]
                  name "sr6"
                  boundingObject USE r6
                  physics Physics {
                    density -1
                    mass 0.1
                  }
                }
              }
              DEF sr7 HingeJoint {
                jointParameters HingeJointParameters {
                  axis -0.707107 0.707107 0
                  anchor -0.04535 -0.04535 0.02
                }
                endPoint Solid {
                  translation -0.04535 -0.04535 0.02
                  rotation -0.7071067811865476 0.7071067811865476 0 0
                  children [
                    DEF r7 Transform {
                      rotation 0 0 1 0.76
                      children [
                        USE SMALL_WHEEL_SHAPE
                      ]
                    }
                  ]
                  name "sr7"
                  boundingObject USE r7
                  physics Physics {
                    density -1
                    mass 0.1
                  }
                }
              }
              DEF sr8 HingeJoint {
                jointParameters HingeJointParameters {
                  axis -0.707107 0.707107 0
                  anchor 0.04535 0.04535 0.02
                }
                endPoint Solid {
                  translation 0.04535 0.04535 0.02
                  rotation -0.7071067811865476 0.7071067811865476 0 0
                  children [
                    DEF r8 Transform {
                      rotation 0 0 1 0.76
                      children [
                        USE SMALL_WHEEL_SHAPE
                      ]
                    }
                  ]
                  name "sr8"
                  boundingObject USE r8
                  physics Physics {
                    density -1
                    mass 0.1
                  }
                }
              }
              DEF WHEEL_TRANS Transform {
                translation 0 0 0.02
                rotation 1 0 0 1.5708
                children [
                  USE WHEEL_SHAPE
                ]
              }
            ]
            name "solid(1)"
            boundingObject USE WHEEL_TRANS
            physics Physics {
            }
          }
        }
      ]
    }
    DEF WH_3 Transform {
      translation -0.13 0 -0.069
      rotation 0 0.9999999999999999 0 -2.0944
      children [
        DEF WHEEL1 HingeJoint {
          jointParameters HingeJointParameters {
            axis 0 0 1
            anchor 0 0 0.02
          }
          device [
            RotationalMotor {
              name "wheel3"
              maxVelocity 30.3687
              maxTorque 0.8473
            }
            PositionSensor {
              name "ps_3"
              resolution 0.003848
            }
          ]
          endPoint Solid {
            translation 0 0 -0.009999999999999998
            rotation 0 0 1 0
            children [
              DEF sr1 HingeJoint {
                jointParameters HingeJointParameters {
                  anchor 0 0.06 0.02
                }
                endPoint Solid {
                  translation 0 0.06 0.02
                  rotation 1 0 0 0
                  children [
                    DEF r1 Transform {
                      rotation 0 0 1 1.5708
                      children [
                        DEF SMALL_WHEEL_SHAPE Shape {
                          appearance PBRAppearance {
                            baseColor 1 0.752941 0.796078
                            roughness 1
                            metalness 0
                          }
                          geometry Cylinder {
                            height 0.03
                            radius 0.012
                          }
                        }
                      ]
                    }
                  ]
                  name "sr1"
                  boundingObject USE r1
                  physics Physics {
                    density -1
                    mass 0.1
                  }
                }
              }
              DEF sr2 HingeJoint {
                jointParameters HingeJointParameters {
                  axis 0.707107 0.707107 0
                  anchor -0.04535 0.04535 0.02
                }
                endPoint Solid {
                  translation -0.04535 0.04535 0.02
                  rotation 0.7071067811865476 0.7071067811865476 0 0
                  children [
                    DEF r2 Transform {
                      rotation 0 0 1 2.27
                      children [
                        USE SMALL_WHEEL_SHAPE
                      ]
                    }
                  ]
                  name "sr2"
                  boundingObject USE r2
                  physics Physics {
                    density -1
                    mass 0.1
                  }
                }
              }
              DEF sr3 HingeJoint {
                jointParameters HingeJointParameters {
                  anchor 0 -0.06 0.02
                }
                endPoint Solid {
                  translation 0 -0.06 0.02
                  rotation 1 0 0 0
                  children [
                    DEF r3 Transform {
                      rotation 0 0 1 1.5708
                      children [
                        USE SMALL_WHEEL_SHAPE
                      ]
                    }
                  ]
                  name "sr3"
                  boundingObject USE r3
                  physics Physics {
                    density -1
                    mass 0.1
                  }
                }
              }
              DEF sr4 HingeJoint {
                jointParameters HingeJointParameters {
                  axis 0.707107 0.707107 0
                  anchor 0.04535 -0.04535 0.02
                }
                endPoint Solid {
                  translation 0.04535 -0.04535 0.02
                  rotation 0.7071067811865476 0.7071067811865476 0 0
                  children [
                    DEF r4 Transform {
                      rotation 0 0 1 2.27
                      children [
                        USE SMALL_WHEEL_SHAPE
                      ]
                    }
                  ]
                  name "sr4"
                  boundingObject USE r4
                  physics Physics {
                    density -1
                    mass 0.1
                  }
                }
              }
              DEF sr5 HingeJoint {
                jointParameters HingeJointParameters {
                  axis 0 1 0
                  anchor -0.06 0 0.02
                }
                endPoint Solid {
                  translation -0.06 0 0.02
                  children [
                    DEF r5 Transform {
                      children [
                        USE SMALL_WHEEL_SHAPE
                      ]
                    }
                  ]
                  name "sr5"
                  boundingObject USE r5
                  physics Physics {
                    density -1
                    mass 0.1
                  }
                }
              }
              DEF sr6 HingeJoint {
                jointParameters HingeJointParameters {
                  axis 0 1 0
                  anchor 0.06 0 0.02
                }
                endPoint Solid {
                  translation 0.06 0 0.02
                  children [
                    DEF r6 Transform {
                      children [
                        USE SMALL_WHEEL_SHAPE
                      ]
                    }
                  ]
                  name "sr6"
                  boundingObject USE r6
                  physics Physics {
                    density -1
                    mass 0.1
                  }
                }
              }
              DEF sr7 HingeJoint {
                jointParameters HingeJointParameters {
                  axis -0.707107 0.707107 0
                  anchor -0.04535 -0.04535 0.02
                }
                endPoint Solid {
                  translation -0.04535 -0.04535 0.02
                  rotation -0.7071067811865476 0.7071067811865476 0 0
                  children [
                    DEF r7 Transform {
                      rotation 0 0 1 0.76
                      children [
                        USE SMALL_WHEEL_SHAPE
                      ]
                    }
                  ]
                  name "sr7"
                  boundingObject USE r7
                  physics Physics {
                    density -1
                    mass 0.1
                  }
                }
              }
              DEF sr8 HingeJoint {
                jointParameters HingeJointParameters {
                  axis -0.707107 0.707107 0
                  anchor 0.04535 0.04535 0.02
                }
                endPoint Solid {
                  translation 0.04535 0.04535 0.02
                  rotation -0.7071067811865476 0.7071067811865476 0 0
                  children [
                    DEF r8 Transform {
                      rotation 0 0 1 0.76
                      children [
                        USE SMALL_WHEEL_SHAPE
                      ]
                    }
                  ]
                  name "sr8"
                  boundingObject USE r8
                  physics Physics {
                    density -1
                    mass 0.1
                  }
                }
              }
              DEF WHEEL_TRANS Transform {
                translation 0 0 0.02
                rotation 1 0 0 1.5708
                children [
                  USE WHEEL_SHAPE
                ]
              }
            ]
            name "solid(2)"
            boundingObject USE WHEEL_TRANS
            physics Physics {
            }
          }
        }
      ]
    }
  ]
  boundingObject USE BODY
  physics Physics {
  }
  controller "u3_real_exam_munoz_samara"
}
